2023-08-13 20:15:25,757 Job "TS_Authenticator.refresh (trigger: cron[day_of_week='mon-fri', minute='14-59/15', second='55'], next run at: 2023-08-14 00:29:55 UTC)" raised an exception
Traceback (most recent call last):
  File "/Users/mattjzhou/opt/miniconda3/envs/trading_env/lib/python3.11/site-packages/apscheduler/executors/base.py", line 125, in run_job
    retval = job.func(*job.args, **job.kwargs)
             ^^^^^^^^^^^^^^^^^^^^^^^^^^^^^^^^^
  File "/Users/mattjzhou/riverhill/tradestation_authenticator.py", line 51, in refresh
    {"$set": newdict}, upsert=True)
  File "/Users/mattjzhou/opt/miniconda3/envs/trading_env/lib/python3.11/site-packages/pymongo/collection.py", line 998, in update_one
    self._update_retryable(
  File "/Users/mattjzhou/opt/miniconda3/envs/trading_env/lib/python3.11/site-packages/pymongo/collection.py", line 854, in _update_retryable
    return self.__database.client._retryable_write(
           ^^^^^^^^^^^^^^^^^^^^^^^^^^^^^^^^^^^^^^^^
  File "/Users/mattjzhou/opt/miniconda3/envs/trading_env/lib/python3.11/site-packages/pymongo/mongo_client.py", line 1490, in _retryable_write
    with self._tmp_session(session) as s:
  File "/Users/mattjzhou/opt/miniconda3/envs/trading_env/lib/python3.11/contextlib.py", line 137, in __enter__
    return next(self.gen)
           ^^^^^^^^^^^^^^
  File "/Users/mattjzhou/opt/miniconda3/envs/trading_env/lib/python3.11/site-packages/pymongo/mongo_client.py", line 1819, in _tmp_session
    s = self._ensure_session(session)
        ^^^^^^^^^^^^^^^^^^^^^^^^^^^^^
  File "/Users/mattjzhou/opt/miniconda3/envs/trading_env/lib/python3.11/site-packages/pymongo/mongo_client.py", line 1806, in _ensure_session
    return self.__start_session(True, causal_consistency=False)
           ^^^^^^^^^^^^^^^^^^^^^^^^^^^^^^^^^^^^^^^^^^^^^^^^^^^^
  File "/Users/mattjzhou/opt/miniconda3/envs/trading_env/lib/python3.11/site-packages/pymongo/mongo_client.py", line 1759, in __start_session
    server_session = self._get_server_session()
                     ^^^^^^^^^^^^^^^^^^^^^^^^^^
  File "/Users/mattjzhou/opt/miniconda3/envs/trading_env/lib/python3.11/site-packages/pymongo/mongo_client.py", line 1792, in _get_server_session
    return self._topology.get_server_session()
           ^^^^^^^^^^^^^^^^^^^^^^^^^^^^^^^^^^^
  File "/Users/mattjzhou/opt/miniconda3/envs/trading_env/lib/python3.11/site-packages/pymongo/topology.py", line 482, in get_server_session
    self._select_servers_loop(
  File "/Users/mattjzhou/opt/miniconda3/envs/trading_env/lib/python3.11/site-packages/pymongo/topology.py", line 208, in _select_servers_loop
    raise ServerSelectionTimeoutError(
pymongo.errors.ServerSelectionTimeoutError: 192.168.1.181:27017: timed out
2023-08-13 20:30:25,551 Job "TS_Authenticator.refresh (trigger: cron[day_of_week='mon-fri', minute='14-59/15', second='55'], next run at: 2023-08-14 00:44:55 UTC)" raised an exception
Traceback (most recent call last):
  File "/Users/mattjzhou/opt/miniconda3/envs/trading_env/lib/python3.11/site-packages/apscheduler/executors/base.py", line 125, in run_job
    retval = job.func(*job.args, **job.kwargs)
             ^^^^^^^^^^^^^^^^^^^^^^^^^^^^^^^^^
  File "/Users/mattjzhou/riverhill/tradestation_authenticator.py", line 51, in refresh
    {"$set": newdict}, upsert=True)
  File "/Users/mattjzhou/opt/miniconda3/envs/trading_env/lib/python3.11/site-packages/pymongo/collection.py", line 998, in update_one
    self._update_retryable(
  File "/Users/mattjzhou/opt/miniconda3/envs/trading_env/lib/python3.11/site-packages/pymongo/collection.py", line 854, in _update_retryable
    return self.__database.client._retryable_write(
           ^^^^^^^^^^^^^^^^^^^^^^^^^^^^^^^^^^^^^^^^
  File "/Users/mattjzhou/opt/miniconda3/envs/trading_env/lib/python3.11/site-packages/pymongo/mongo_client.py", line 1490, in _retryable_write
    with self._tmp_session(session) as s:
  File "/Users/mattjzhou/opt/miniconda3/envs/trading_env/lib/python3.11/contextlib.py", line 137, in __enter__
    return next(self.gen)
           ^^^^^^^^^^^^^^
  File "/Users/mattjzhou/opt/miniconda3/envs/trading_env/lib/python3.11/site-packages/pymongo/mongo_client.py", line 1819, in _tmp_session
    s = self._ensure_session(session)
        ^^^^^^^^^^^^^^^^^^^^^^^^^^^^^
  File "/Users/mattjzhou/opt/miniconda3/envs/trading_env/lib/python3.11/site-packages/pymongo/mongo_client.py", line 1806, in _ensure_session
    return self.__start_session(True, causal_consistency=False)
           ^^^^^^^^^^^^^^^^^^^^^^^^^^^^^^^^^^^^^^^^^^^^^^^^^^^^
  File "/Users/mattjzhou/opt/miniconda3/envs/trading_env/lib/python3.11/site-packages/pymongo/mongo_client.py", line 1759, in __start_session
    server_session = self._get_server_session()
                     ^^^^^^^^^^^^^^^^^^^^^^^^^^
  File "/Users/mattjzhou/opt/miniconda3/envs/trading_env/lib/python3.11/site-packages/pymongo/mongo_client.py", line 1792, in _get_server_session
    return self._topology.get_server_session()
           ^^^^^^^^^^^^^^^^^^^^^^^^^^^^^^^^^^^
  File "/Users/mattjzhou/opt/miniconda3/envs/trading_env/lib/python3.11/site-packages/pymongo/topology.py", line 482, in get_server_session
    self._select_servers_loop(
  File "/Users/mattjzhou/opt/miniconda3/envs/trading_env/lib/python3.11/site-packages/pymongo/topology.py", line 208, in _select_servers_loop
    raise ServerSelectionTimeoutError(
pymongo.errors.ServerSelectionTimeoutError: 192.168.1.181:27017: timed out
2023-08-13 20:45:25,690 Job "TS_Authenticator.refresh (trigger: cron[day_of_week='mon-fri', minute='14-59/15', second='55'], next run at: 2023-08-14 00:59:55 UTC)" raised an exception
Traceback (most recent call last):
  File "/Users/mattjzhou/opt/miniconda3/envs/trading_env/lib/python3.11/site-packages/apscheduler/executors/base.py", line 125, in run_job
    retval = job.func(*job.args, **job.kwargs)
             ^^^^^^^^^^^^^^^^^^^^^^^^^^^^^^^^^
  File "/Users/mattjzhou/riverhill/tradestation_authenticator.py", line 51, in refresh
    {"$set": newdict}, upsert=True)
  File "/Users/mattjzhou/opt/miniconda3/envs/trading_env/lib/python3.11/site-packages/pymongo/collection.py", line 998, in update_one
    self._update_retryable(
  File "/Users/mattjzhou/opt/miniconda3/envs/trading_env/lib/python3.11/site-packages/pymongo/collection.py", line 854, in _update_retryable
    return self.__database.client._retryable_write(
           ^^^^^^^^^^^^^^^^^^^^^^^^^^^^^^^^^^^^^^^^
  File "/Users/mattjzhou/opt/miniconda3/envs/trading_env/lib/python3.11/site-packages/pymongo/mongo_client.py", line 1490, in _retryable_write
    with self._tmp_session(session) as s:
  File "/Users/mattjzhou/opt/miniconda3/envs/trading_env/lib/python3.11/contextlib.py", line 137, in __enter__
    return next(self.gen)
           ^^^^^^^^^^^^^^
  File "/Users/mattjzhou/opt/miniconda3/envs/trading_env/lib/python3.11/site-packages/pymongo/mongo_client.py", line 1819, in _tmp_session
    s = self._ensure_session(session)
        ^^^^^^^^^^^^^^^^^^^^^^^^^^^^^
  File "/Users/mattjzhou/opt/miniconda3/envs/trading_env/lib/python3.11/site-packages/pymongo/mongo_client.py", line 1806, in _ensure_session
    return self.__start_session(True, causal_consistency=False)
           ^^^^^^^^^^^^^^^^^^^^^^^^^^^^^^^^^^^^^^^^^^^^^^^^^^^^
  File "/Users/mattjzhou/opt/miniconda3/envs/trading_env/lib/python3.11/site-packages/pymongo/mongo_client.py", line 1759, in __start_session
    server_session = self._get_server_session()
                     ^^^^^^^^^^^^^^^^^^^^^^^^^^
  File "/Users/mattjzhou/opt/miniconda3/envs/trading_env/lib/python3.11/site-packages/pymongo/mongo_client.py", line 1792, in _get_server_session
    return self._topology.get_server_session()
           ^^^^^^^^^^^^^^^^^^^^^^^^^^^^^^^^^^^
  File "/Users/mattjzhou/opt/miniconda3/envs/trading_env/lib/python3.11/site-packages/pymongo/topology.py", line 482, in get_server_session
    self._select_servers_loop(
  File "/Users/mattjzhou/opt/miniconda3/envs/trading_env/lib/python3.11/site-packages/pymongo/topology.py", line 208, in _select_servers_loop
    raise ServerSelectionTimeoutError(
pymongo.errors.ServerSelectionTimeoutError: 192.168.1.181:27017: timed out
2023-08-13 21:00:25,877 Job "TS_Authenticator.refresh (trigger: cron[day_of_week='mon-fri', minute='14-59/15', second='55'], next run at: 2023-08-14 01:14:55 UTC)" raised an exception
Traceback (most recent call last):
  File "/Users/mattjzhou/opt/miniconda3/envs/trading_env/lib/python3.11/site-packages/apscheduler/executors/base.py", line 125, in run_job
    retval = job.func(*job.args, **job.kwargs)
             ^^^^^^^^^^^^^^^^^^^^^^^^^^^^^^^^^
  File "/Users/mattjzhou/riverhill/tradestation_authenticator.py", line 51, in refresh
    {"$set": newdict}, upsert=True)
  File "/Users/mattjzhou/opt/miniconda3/envs/trading_env/lib/python3.11/site-packages/pymongo/collection.py", line 998, in update_one
    self._update_retryable(
  File "/Users/mattjzhou/opt/miniconda3/envs/trading_env/lib/python3.11/site-packages/pymongo/collection.py", line 854, in _update_retryable
    return self.__database.client._retryable_write(
           ^^^^^^^^^^^^^^^^^^^^^^^^^^^^^^^^^^^^^^^^
  File "/Users/mattjzhou/opt/miniconda3/envs/trading_env/lib/python3.11/site-packages/pymongo/mongo_client.py", line 1490, in _retryable_write
    with self._tmp_session(session) as s:
  File "/Users/mattjzhou/opt/miniconda3/envs/trading_env/lib/python3.11/contextlib.py", line 137, in __enter__
    return next(self.gen)
           ^^^^^^^^^^^^^^
  File "/Users/mattjzhou/opt/miniconda3/envs/trading_env/lib/python3.11/site-packages/pymongo/mongo_client.py", line 1819, in _tmp_session
    s = self._ensure_session(session)
        ^^^^^^^^^^^^^^^^^^^^^^^^^^^^^
  File "/Users/mattjzhou/opt/miniconda3/envs/trading_env/lib/python3.11/site-packages/pymongo/mongo_client.py", line 1806, in _ensure_session
    return self.__start_session(True, causal_consistency=False)
           ^^^^^^^^^^^^^^^^^^^^^^^^^^^^^^^^^^^^^^^^^^^^^^^^^^^^
  File "/Users/mattjzhou/opt/miniconda3/envs/trading_env/lib/python3.11/site-packages/pymongo/mongo_client.py", line 1759, in __start_session
    server_session = self._get_server_session()
                     ^^^^^^^^^^^^^^^^^^^^^^^^^^
  File "/Users/mattjzhou/opt/miniconda3/envs/trading_env/lib/python3.11/site-packages/pymongo/mongo_client.py", line 1792, in _get_server_session
    return self._topology.get_server_session()
           ^^^^^^^^^^^^^^^^^^^^^^^^^^^^^^^^^^^
  File "/Users/mattjzhou/opt/miniconda3/envs/trading_env/lib/python3.11/site-packages/pymongo/topology.py", line 482, in get_server_session
    self._select_servers_loop(
  File "/Users/mattjzhou/opt/miniconda3/envs/trading_env/lib/python3.11/site-packages/pymongo/topology.py", line 208, in _select_servers_loop
    raise ServerSelectionTimeoutError(
pymongo.errors.ServerSelectionTimeoutError: 192.168.1.181:27017: timed out
2023-08-13 21:15:25,765 Job "TS_Authenticator.refresh (trigger: cron[day_of_week='mon-fri', minute='14-59/15', second='55'], next run at: 2023-08-14 01:29:55 UTC)" raised an exception
Traceback (most recent call last):
  File "/Users/mattjzhou/opt/miniconda3/envs/trading_env/lib/python3.11/site-packages/apscheduler/executors/base.py", line 125, in run_job
    retval = job.func(*job.args, **job.kwargs)
             ^^^^^^^^^^^^^^^^^^^^^^^^^^^^^^^^^
  File "/Users/mattjzhou/riverhill/tradestation_authenticator.py", line 51, in refresh
  File "/Users/mattjzhou/opt/miniconda3/envs/trading_env/lib/python3.11/site-packages/pymongo/collection.py", line 998, in update_one
    self._update_retryable(
  File "/Users/mattjzhou/opt/miniconda3/envs/trading_env/lib/python3.11/site-packages/pymongo/collection.py", line 854, in _update_retryable
    return self.__database.client._retryable_write(
           ^^^^^^^^^^^^^^^^^^^^^^^^^^^^^^^^^^^^^^^^
  File "/Users/mattjzhou/opt/miniconda3/envs/trading_env/lib/python3.11/site-packages/pymongo/mongo_client.py", line 1490, in _retryable_write
    with self._tmp_session(session) as s:
  File "/Users/mattjzhou/opt/miniconda3/envs/trading_env/lib/python3.11/contextlib.py", line 137, in __enter__
    return next(self.gen)
           ^^^^^^^^^^^^^^
  File "/Users/mattjzhou/opt/miniconda3/envs/trading_env/lib/python3.11/site-packages/pymongo/mongo_client.py", line 1819, in _tmp_session
    s = self._ensure_session(session)
        ^^^^^^^^^^^^^^^^^^^^^^^^^^^^^
  File "/Users/mattjzhou/opt/miniconda3/envs/trading_env/lib/python3.11/site-packages/pymongo/mongo_client.py", line 1806, in _ensure_session
    return self.__start_session(True, causal_consistency=False)
           ^^^^^^^^^^^^^^^^^^^^^^^^^^^^^^^^^^^^^^^^^^^^^^^^^^^^
  File "/Users/mattjzhou/opt/miniconda3/envs/trading_env/lib/python3.11/site-packages/pymongo/mongo_client.py", line 1759, in __start_session
    server_session = self._get_server_session()
                     ^^^^^^^^^^^^^^^^^^^^^^^^^^
  File "/Users/mattjzhou/opt/miniconda3/envs/trading_env/lib/python3.11/site-packages/pymongo/mongo_client.py", line 1792, in _get_server_session
    return self._topology.get_server_session()
           ^^^^^^^^^^^^^^^^^^^^^^^^^^^^^^^^^^^
  File "/Users/mattjzhou/opt/miniconda3/envs/trading_env/lib/python3.11/site-packages/pymongo/topology.py", line 482, in get_server_session
    self._select_servers_loop(
  File "/Users/mattjzhou/opt/miniconda3/envs/trading_env/lib/python3.11/site-packages/pymongo/topology.py", line 208, in _select_servers_loop
    raise ServerSelectionTimeoutError(
pymongo.errors.ServerSelectionTimeoutError: 192.168.1.181:27017: timed out
